Workbook

Sheet 가정
A1: Kindy 재무모델 v1.3 — 가정 (Assumptions) · 검증상태 관리
A2: 색상: 파랑=입력값(수정 가능) / 검정=수식 / 초록=타 시트 링크 / 노랑배경=핵심 가정
A4: 시나리오 선택 (1=보수 / 2=기본 / 3=낙관) | B4: 2 | C4: 보수 | D4: 기본 | E4: 낙관 | G4: 검증상태
A6: ── B2C 가격 ──
A7: 베타 월 구독료 (VAT포함, ₩) | B7: 19000 | F7: 얼리버드: 첫 6개월 신규 대상. 근거: 백서 v1.1 §8.4 | G7: 결정(P-1 도서관한정)
A8: 정가 월 구독료 (VAT포함, ₩) | B8: 25000 | F8: 근거: IR ARPU 25,000 / 백서 스위트스팟 | G8: 결정
A9: 베타 가격 적용 종료월 (M) | B9: 6 | F9: M7부터 정가 | G9: 결정(12개월 락)
A10: 얼리버드 락인 ARPU 희석률 | B10: 0.08 | F10: 락인 가구 잔존으로 정가 대비 blended ARPU 하락분(추정) | G10: 가정→M7 실측
A11: 형제 프로필 attach율 | B11: 0.1 | F11: 가구당 자녀 추가 프로필 | G11: 가정→M3 실측
A12: 형제 프로필 월가 (VAT포함, ₩) | B12: 7000
A13: 연간플랜 비중 (신규 중) | B13: 0 | F13: 기본 0%. 활성화 시 현금 선수 효과가 현금 시트에 반영 | G13: 결정(기본 0%)
A14: 연간플랜 가격 (VAT포함, ₩) | B14: 190000 | F14: 월 15,833 효과 = 17% 할인
A16: ── 퍼널 (도서관 키오스크) ──
A17: 키오스크 세션 수 / 관 / 월 | B17: 1200 | F17: 일 40세션 × 30일. 실측치로 교체 필요(스프린트 W2 계측) | G17: 가정→W2 실측
A18: 세션→QR 스캔율 | B18: =CHOOSE($B$4,C18,D18,E18) -> 0.06 | C18: 0.04 | D18: 0.06 | E18: 0.08 | F18: ★ 최대 불확실 변수. W2 실측으로 교체 | G18: ★가정→W2 실측
A19: QR→가입(부모동의) 완료율 | B19: 0.45 | F19: PIPA 동의 플로우 포함 | G19: 가정→W3 실측
A20: 가입→무료체험(3세션) 시작률 | B20: 0.6 | G20: 가정→W3 실측
A21: 체험→유료 전환율 | B21: =CHOOSE($B$4,C21,D21,E21) -> 0.45 | C21: 0.35 | D21: 0.45 | E21: 0.55 | F21: 근거: 온보딩 리서치 트라이얼→유료 중앙값 50~60% | G21: ★가정→W5 실측
A22: 월 이탈률 (churn) | B22: =CHOOSE($B$4,C22,D22,E22) -> 0.25 | C22: 0.35 | D22: 0.25 | E22: 0.15 | F22: 근거: 백서 v1.1 §8.1 | G22: ★W7 W4유지→M4 steady
A24: ── Paid 마케팅 ──
A25: 목표 CAC (paid, ₩) | B25: 30000 | F25: 근거: IR paid IG=30K. W5 실측으로 검증 | G25: 가정→W5 실측
A27: ── 변동원가 (가구당/월) ──
A28: 결제수수료율 (결제액 대비) | B28: 0.034 | F28: Toss 일반 카드 3.4% 기준. 영세(연매출 3억 미만) 우대는 확정 후 자동반영/환급 구조 확인 | G28: 실측(계약 확인)
A29: 인프라·스트리밍 (₩) | B29: 1200 | F29: CDN egress+Supabase+GCS, 월 4시간 시청 가정 | G29: 가정→M2 실측
A30: 개인화 L2 호명 등 (₩) | B30: 100 | F30: TTS 이름 세그먼트 | G30: 폐기(티어로 대체)
A32: ── 콘텐츠 제작 (고정성 원가) ──
A33: 에피소드 제작 원가 / 편 (₩) | B33: 200000 | F33: 4~5분 에피소드, AI 파이프라인 기준(모델 스택 마스터플랜 참조) | G33: 가정→R1 실측
A34: 월 신규 에피소드 수 | B34: 8 | F34: 근거: 백서 §8.2 소진 대응 | G34: 운영 결정값
A36: ── B2G ──
A37: 도서관 관당 연 라이선스 (공급가, ₩) | B37: 18000000 | F37: Standard 티어. 수의계약 한도(소기업 5천만) 내 설계 | G37: 계약별 실측
A39: ── 세율·부대율 ──
A40: 부가가치세율 | B40: 0.1 | G40: 법정
A41: 인건비 부대율 (4대보험+퇴직급여) | B41: 0.19 | F41: 사업주 4대보험 ~10.5% + 퇴직급여 8.33% | G41: 법정+정책
A43: ── 자금 ──
A44: Seed 납입액 (₩, M1) | B44: 300000000 | F44: IR: 3억 / post 30억 / 10% | G44: 실측(납입)
A47: ── 인건비 계획 (역할 / 월급여 / 시작월) ──
A48: 역할 | B48: 월급여(₩) | C48: 시작월
A49: CEO (최소화) | B49: 3000000 | C49: 1
A50: 개발자 A | B50: 4500000 | C50: 1
A51: 디자이너 (PT) | B51: 2000000 | C51: 1
...

Sheet 가입자
A1: 가입자·B2C 매출 모델 (M1 = 2026-07)
A3: 월 (M) | C3: 1 | D3: 2 | E3: 3 | F3: 4 | G3: 5 | H3: 6 | I3: 7 | J3: 8 | K3: 9 | L3: 10 | M3: 11 | N3: 12 | O3: 13 | P3: 14 | Q3: 15 | R3: 16 | S3: 17 | T3: 18 | U3: 19 | V3: 20 | W3: 21 | X3: 22 | Y3: 23 | Z3: 24 | AA3: 25 | AB3: 26 | AC3: 27 | AD3: 28 | AE3: 29 | AF3: 30 | AG3: 31 | AH3: 32 | AI3: 33 | AJ3: 34 | AK3: 35 | AL3: 36
A4: 연월 | C4: 2026-07 | D4: 2026-08 | E4: 2026-09 | F4: 2026-10 | G4: 2026-11 | H4: 2026-12 | I4: 2027-01 | J4: 2027-02 | K4: 2027-03 | L4: 2027-04 | M4: 2027-05 | N4: 2027-06 | O4: 2027-07 | P4: 2027-08 | Q4: 2027-09 | R4: 2027-10 | S4: 2027-11 | T4: 2027-12 | U4: 2028-01 | V4: 2028-02 | W4: 2028-03 | X4: 2028-04 | Y4: 2028-05 | Z4: 2028-06 | AA4: 2028-07 | AB4: 2028-08 | AC4: 2028-09 | AD4: 2028-10 | AE4: 2028-11 | AF4: 2028-12 | AG4: 2029-01 | AH4: 2029-02 | AI4: 2029-03 | AJ4: 2029-04 | AK4: 2029-05 | AL4: 2029-06
A5: 운영 도서관 수 [입력] | B5: 관 | C5: 2 | D5: 3 | E5: 5 | F5: 6 | G5: 7 | H5: 8 | I5: 10 | J5: 12 | K5: 15 | L5: 17 | M5: 19 | N5: 22 | O5: 25 | P5: 28 | Q5: 31 | R5: 34 | S5: 37 | T5: 40 | U5: 44 | V5: 48 | W5: 52 | X5: 56 | Y5: 60 | Z5: 65 | AA5: 70 | AB5: 75 | AC5: 80 | AD5: 85 | AE5: 90 | AF5: 95 | AG5: 100 | AH5: 105 | AI5: 110 | AJ5: 115 | AK5: 120 | AL5: 125
A6: 키오스크 세션 수 | B6: 건 | C6: =C5*가정!$B$17 -> 2400 | D6: =D5*가정!$B$17 -> 3600 | E6: =E5*가정!$B$17 -> 6000 | F6: =F5*가정!$B$17 -> 7200 | G6: =G5*가정!$B$17 -> 8400 | H6: =H5*가정!$B$17 -> 9600 | I6: =I5*가정!$B$17 -> 12000 | J6: =J5*가정!$B$17 -> 14400 | ... AL6: =AL5*가정!$B$17 -> 150000
A7: QR 스캔 | B7: 건 | C7: =C6*가정!$B$18 -> 144 | D7: =D6*가정!$B$18 -> 216 | E7: =E6*가정!$B$18 -> 360 | F7: =F6*가정!$B$18 -> 432 | G7: =G6*가정!$B$18 -> 504 | H7: =H6*가정!$B$18 -> 576 | I7: =I6*가정!$B$18 -> 720 | J7: =J6*가정!$B$18 -> 864 | ... AL7: =AL6*가정!$B$18 -> 9000
A8: 가입 완료 | B8: 가구 | C8: =C7*가정!$B$19 -> 64.8 | D8: =D7*가정!$B$19 -> 97.2 | E8: =E7*가정!$B$19 -> 162 | F8: =F7*가정!$B$19 -> 194.4 | G8: =G7*가정!$B$19 -> 226.8 | H8: =H7*가정!$B$19 -> 259.2 | I8: =I7*가정!$B$19 -> 324 | J8: =J7*가정!$B$19 -> 388.8 | ... AL8: =AL7*가정!$B$19 -> 4050
A9: 무료체험 시작 | B9: 가구 | C9: =C8*가정!$B$20 -> 38.88 | D9: =D8*가정!$B$20 -> 58.32 | E9: =E8*가정!$B$20 -> 97.2 | F9: =F8*가정!$B$20 -> 116.64 | G9: =G8*가정!$B$20 -> 136.08 | H9: =H8*가정!$B$20 -> 155.52 | I9: =I8*가정!$B$20 -> 194.4 | J9: =J8*가정!$B$20 -> 233.28 | ... AL9: =AL8*가정!$B$20 -> 2430
A10: 오가닉 신규 유료 | B10: 가구 | C10: =C9*가정!$B$21 -> 17.496 | D10: =D9*가정!$B$21 -> 26.244 | E10: =E9*가정!$B$21 -> 43.74 | F10: =F9*가정!$B$21 -> 52.488 | G10: =G9*가정!$B$21 -> 61.236 | H10: =H9*가정!$B$21 -> 69.984 | I10: =I9*가정!$B$21 -> 87.48 | J10: =J9*가정!$B$21 -> 104.976 | ... AL10: =AL9*가정!$B$21 -> 1093.5
A11: 마케팅 예산 [입력] | B11: ₩ | C11: 0 | D11: 1000000 | E11: 2000000 | F11: 3000000 | G11: 3000000 | H11: 3000000 | I11: 5000000 | J11: 5000000 | K11: 5000000 | L11: 8000000 | M11: 8000000 | N11: 8000000 | O11: 12000000 | P11: 12000000 | Q11: 12000000 | R11: 12000000 | S11: 12000000 | T11: 12000000 | U11: 20000000 | V11: 20000000 | W11: 20000000 | X11: 20000000 | Y11: 20000000 | Z11: 20000000 | AA11: 30000000 | AB11: 30000000 | AC11: 30000000 | AD11: 30000000 | AE11: 30000000 | AF11: 30000000 | AG11: 30000000 | AH11: 30000000 | AI11: 30000000 | AJ11: 30000000 | AK11: 30000000 | AL11: 30000000
A12: Paid 신규 유료 | B12: 가구 | C12: =C11/가정!$B$25 -> 0 | D12: =D11/가정!$B$25 -> 33.333333 | E12: =E11/가정!$B$25 -> 66.666667 | F12: =F11/가정!$B$25 -> 100 | G12: =G11/가정!$B$25 -> 100 | H12: =H11/가정!$B$25 -> 100 | I12: =I11/가정!$B$25 -> 166.66667 | J12: =J11/가정!$B$25 -> 166.66667 | ... AL12: =AL11/가정!$B$25 -> 1000
A13: 총 신규 유료 | B13: 가구 | C13: =C10+C12 -> 17.496 | D13: =D10+D12 -> 59.577333 | E13: =E10+E12 -> 110.40667 | F13: =F10+F12 -> 152.488 | G13: =G10+G12 -> 161.236 | H13: =H10+H12 -> 169.984 | I13: =I10+I12 -> 254.14667 | J13: =J10+J12 -> 271.64267 | ... AL13: =AL10+AL12 -> 2093.5
A14: 이탈 | B14: 가구 | C14: 0 | D14: =C15*가정!$B$22 -> 4.374 | E14: =D15*가정!$B$22 -> 18.174833 | F14: =E15*가정!$B$22 -> 41.232792 | G14: =F15*가정!$B$22 -> 69.046594 | H14: =G15*가정!$B$22 -> 92.093945 | I14: =H15*가정!$B$22 -> 111.56646 | J14: =I15*가정!$B$22 -> 147.21151 | K14: =J15*가정!$B$22 -> 178.3193 | ... AL14: =AK15*가정!$B$22 -> 1903.2562
A15: 기말 유료 가구 | B15: 가구 | C15: =C13 -> 17.496 | D15: =C15+D13-D14 -> 72.699333 | E15: =D15+E13-E14 -> 164.93117 | F15: =E15+F13-F14 -> 276.18637 | G15: =F15+G13-G14 -> 368.37578 | H15: =G15+H13-H14 -> 446.26584 | I15: =H15+I13-I14 -> 588.84604 | J15: =I15+J13-J14 -> 713.2772 | K15: =J15+K13-K14 -> 832.84457 | ... AL15: =AK15+AL13-AL14 -> 7803.2686
A16: 연간플랜 신규 | B16: 가구 | C16: =C13*가정!$B$13 -> 0 | D16: =D13*가정!$B$13 -> 0 | E16: =E13*가정!$B$13 -> 0 | F16: =F13*가정!$B$13 -> 0 | G16: =G13*가정!$B$13 -> 0 | H16: =H13*가정!$B$13 -> 0 | I16: =I13*가정!$B$13 -> 0 | J16: =J13*가정!$B$13 -> 0 | ... AL16: =AL13*가정!$B$13 -> 0
A17: 연간플랜 활성 | B17: 가구 | C17: =SUM(C16:C16) -> 0 | D17: =SUM(C16:D16) -> 0 | E17: =SUM(C16:E16) -> 0 | F17: =SUM(C16:F16) -> 0 | G17: =SUM(C16:G16) -> 0 | H17: =SUM(C16:H16) -> 0 | I17: =SUM(C16:I16) -> 0 | J17: =SUM(C16:J16) -> 0 | K17: =SUM(C16:K16) -> 0 | L17: =SUM(C16:L16) -> 0 | M17: =SUM(C16:M16) -> 0 | N17: =SUM(C16:N16) -> 0 | O17: =SUM(D16:O16) -> 0 | P17: =SUM(E16:P16) -> 0 | Q17: =SUM(F16:Q16) -> 0 | R17: =SUM(G16:R16) -> 0 | S17: =SUM(H16:S16) -> 0 | T17: =SUM(I16:T16) -> 0 | U17: =SUM(J16:U16) -> 0 | ... AL17: =SUM(AA16:AL16) -> 0
A18: 월간플랜 활성 | B18: 가구 | C18: =C15-C17 -> 17.496 | D18: =D15-D17 -> 72.699333 | E18: =E15-E17 -> 164.93117 | F18: =F15-F17 -> 276.18637 | G18: =G15-G17 -> 368.37578 | H18: =H15-H17 -> 446.26584 | I18: =I15-I17 -> 588.84604 | J18: =J15-J17 -> 713.2772 | ... AL18: =AL15-AL17 -> 7803.2686
A19: 적용 월 ARPU (VAT포함) | B19: ₩ | C19: =IF(C3<=가정!$B$9,가정!$B$7,가정!$B$8*(1-가정!$B$10)) -> 19000 | D19: =IF(D3<=가정!$B$9,가정!$B$7,가정!$B$8*(1-가정!$B$10)) -> 19000 | E19: =IF(E3<=가정!$B$9,가정!$B$7,가정!$B$8*(1-가정!$B$10)) -> 19000 | F19: =IF(F3<=가정!$B$9,가정!$B$7,가정!$B$8*(1-가정!$B$10)) -> 19000 | G19: =IF(G3<=가정!$B$9,가정!$B$7,가정!$B$8*(1-가정!$B$10)) -> 19000 | H19: =IF(H3<=가정!$B$9,가정!$B$7,가정!$B$8*(1-가정!$B$10)) -> 19000 | I19: =IF(I3<=가정!$B$9,가정!$B$7,가정!$B$8*(1-가정!$B$10)) -> 23000 | J19: =IF(J3<=가정!$B$9,가정!$B$7,가정!$B$8*(1-가정!$B$10)) -> 23000 | ... AL19: =IF(AL3<=가정!$B$9,가정!$B$7,가정!$B$8*(1-가정!$B$10)) -> 23000
A20: 형제 애드온 결제액 (VAT포함) | B20: ₩ | C20: =C15*가정!$B$11*가정!$B$12 -> 12247.2 | D20: =D15*가정!$B$11*가정!$B$12 -> 50889.533 | E20: =E15*가정!$B$11*가정!$B$12 -> 115451.82 | F20: =F15*가정!$B$11*가정!$B$12 -> 193330.46 | G20: =G15*가정!$B$11*가정!$B$12 -> 257863.05 | H20: =H15*가정!$B$11*가정!$B$12 -> 312386.09 | I20: =I15*가정!$B$11*가정!$B$12 -> 412192.23 | J20: =J15*가정!$B$11*가정!$B$12 -> 499294.04 | ... AL20: =AL15*가정!$B$11*가정!$B$12 -> 5462288
A21: B2C 결제액 (VAT포함, 발생) | B21: ₩ | C21: =C18*C19+C17*가정!$B$14/12+C20 -> 344671.2 | D21: =D18*D19+D17*가정!$B$14/12+D20 -> 1432176.9 | E21: =E18*E19+E17*가정!$B$14/12+E20 -> 3249144 | F21: =F18*F19+F17*가정!$B$14/12+F20 -> 5440871.6 | G21: =G18*G19+G17*가정!$B$14/12+G20 -> 7257002.9 | H21: =H18*H19+H17*가정!$B$14/12+H20 -> 8791437 | I21: =I18*I19+I17*가정!$B$14/12+I20 -> 13955651 | J21: =J18*J19+J17*가정!$B$14/12+J20 -> 16904670 | ... AL21: =AL18*AL19+AL17*가정!$B$14/12+AL20 -> 1.8493747e+08
A22: B2C 순매출 (VAT제외) | B22: ₩ | C22: =C21/(1+가정!$B$40) -> 313337.45 | D22: =D21/(1+가정!$B$40) -> 1301979 | E22: =E21/(1+가정!$B$40) -> 2953767.3 | F22: =F21/(1+가정!$B$40) -> 4946246.9 | G22: =G21/(1+가정!$B$40) -> 6597275.4 | H22: =H21/(1+가정!$B$40) -> 7992215.4 | I22: =I21/(1+가정!$B$40) -> 12686956 | J22: =J21/(1+가정!$B$40) -> 15367881 | ... AL22: =AL21/(1+가정!$B$40) -> 1.6812497e+08
A23: (참고) 월 무료 체험자 | B23: 가구 | C23: =C9 -> 38.88 | D23: =D9 -> 58.32 | E23: =E9 -> 97.2 | F23: =F9 -> 116.64 | G23: =G9 -> 136.08 | H23: =H9 -> 155.52 | I23: =I9 -> 194.4 | J23: =J9 -> 233.28 | ... AL23: =AL9 -> 2430

Sheet 손익
A1: 월별 손익계산서 (발생주의, VAT 제외 순액)
A3: 월 (M) | C3: 1 | D3: 2 | E3: 3 | F3: 4 | G3: 5 | H3: 6 | I3: 7 | J3: 8 | K3: 9 | L3: 10 | M3: 11 | N3: 12 | O3: 13 | P3: 14 | Q3: 15 | R3: 16 | S3: 17 | T3: 18 | U3: 19 | V3: 20 | W3: 21 | X3: 22 | Y3: 23 | Z3: 24 | AA3: 25 | AB3: 26 | AC3: 27 | AD3: 28 | AE3: 29 | AF3: 30 | AG3: 31 | AH3: 32 | AI3: 33 | AJ3: 34 | AK3: 35 | AL3: 36
A4: 연월 | C4: 2026-07 | D4: 2026-08 | E4: 2026-09 | F4: 2026-10 | G4: 2026-11 | H4: 2026-12 | I4: 2027-01 | J4: 2027-02 | K4: 2027-03 | L4: 2027-04 | M4: 2027-05 | N4: 2027-06 | O4: 2027-07 | P4: 2027-08 | Q4: 2027-09 | R4: 2027-10 | S4: 2027-11 | T4: 2027-12 | U4: 2028-01 | V4: 2028-02 | W4: 2028-03 | X4: 2028-04 | Y4: 2028-05 | Z4: 2028-06 | AA4: 2028-07 | AB4: 2028-08 | AC4: 2028-09 | AD4: 2028-10 | AE4: 2028-11 | AF4: 2028-12 | AG4: 2029-01 | AH4: 2029-02 | AI4: 2029-03 | AJ4: 2029-04 | AK4: 2029-05 | AL4: 2029-06
A6: B2C 순매출 | B6: ₩ | C6: =가입자!C22 -> 313337.45 | D6: =가입자!D22 -> 1301979 | E6: =가입자!E22 -> 2953767.3 | F6: =가입자!F22 -> 4946246.9 | G6: =가입자!G22 -> 6597275.4 | H6: =가입자!H22 -> 7992215.4 | I6: =가입자!I22 -> 12686956 | J6: =가입자!J22 -> 15367881 | ... AL6: =가입자!AL22 -> 1.6812497e+08
A7: B2G 유료 관수 [입력] | B7: 관 | C7: 0 | D7: 0 | E7: 1 | F7: 1 | G7: 2 | H7: 2 | I7: 3 | J7: 3 | K7: 4 | L7: 4 | M7: 5 | N7: 5 | O7: 6 | P7: 7 | Q7: 7 | R7: 8 | S7: 9 | T7: 10 | U7: 11 | V7: 12 | W7: 13 | X7: 14 | Y7: 15 | Z7: 16 | AA7: 18 | AB7: 19 | AC7: 21 | AD7: 22 | AE7: 24 | AF7: 25 | AG7: 26 | AH7: 27 | AI7: 28 | AJ7: 29 | AK7: 30 | AL7: 32
A8: B2G 순매출 (월할 인식) | B8: ₩ | C8: =C7*가정!$B$37/12 -> 0 | D8: =D7*가정!$B$37/12 -> 0 | E8: =E7*가정!$B$37/12 -> 1500000 | F8: =F7*가정!$B$37/12 -> 1500000 | G8: =G7*가정!$B$37/12 -> 3000000 | H8: =H7*가정!$B$37/12 -> 3000000 | I8: =I7*가정!$B$37/12 -> 4500000 | J8: =J7*가정!$B$37/12 -> 4500000 | ... AL8: =AL7*가정!$B$37/12 -> 48000000
A9: 총매출 | B9: ₩ | C9: =C6+C8 -> 313337.45 | D9: =D6+D8 -> 1301979 | E9: =E6+E8 -> 4453767.3 | F9: =F6+F8 -> 6446246.9 | G9: =G6+G8 -> 9597275.4 | H9: =H6+H8 -> 10992215 | I9: =I6+I8 -> 17186956 | J9: =J6+J8 -> 19867881 | ... AL9: =AL6+AL8 -> 2.1612497e+08
A11: 결제수수료 | B11: ₩ | C11: =가입자!C21*가정!$B$28 -> 11718.821 | D11: =가입자!D21*가정!$B$28 -> 48694.013 | E11: =가입자!E21*가정!$B$28 -> 110470.9 | F11: =가입자!F21*가정!$B$28 -> 184989.63 | G11: =가입자!G21*가정!$B$28 -> 246738.1 | H11: =가입자!H21*가정!$B$28 -> 298908.86 | I11: =가입자!I21*가정!$B$28 -> 474492.14 | J11: =가입자!J21*가정!$B$28 -> 574758.77 | ... AL11: =가입자!AL21*가정!$B$28 -> 6287873.9
A12: 인프라·스트리밍 | B12: ₩ | C12: =가입자!C15*가정!$B$29 -> 20995.2 | D12: =가입자!D15*가정!$B$29 -> 87239.2 | E12: =가입자!E15*가정!$B$29 -> 197917.4 | F12: =가입자!F15*가정!$B$29 -> 331423.65 | G12: =가입자!G15*가정!$B$29 -> 442050.94 | H12: =가입자!H15*가정!$B$29 -> 535519 | I12: =가입자!I15*가정!$B$29 -> 706615.25 | J12: =가입자!J15*가정!$B$29 -> 855932.64 | ... AL12: =가입자!AL15*가정!$B$29 -> 9363922.4
A13: 개인화 COGS (티어) | B13: ₩ | C13: =가입자!C15*가정!$B$67 -> 20995.2 | D13: =가입자!D15*가정!$B$67 -> 87239.2 | E13: =가입자!E15*가정!$B$67 -> 197917.4 | F13: =가입자!F15*가정!$B$67 -> 331423.65 | G13: =가입자!G15*가정!$B$67 -> 442050.94 | H13: =가입자!H15*가정!$B$67 -> 535519 | I13: =가입자!I15*가정!$B$67 -> 706615.25 | J13: =가입자!J15*가정!$B$67 -> 855932.64 | ... AL13: =가입자!AL15*가정!$B$67 -> 9363922.4
A14: 콘텐츠 제작비 | B14: ₩ | C14: =가정!$B$33*가정!$B$34 -> 1600000 | D14: =가정!$B$33*가정!$B$34 -> 1600000 | E14: =가정!$B$33*가정!$B$34 -> 1600000 | F14: =가정!$B$33*가정!$B$34 -> 1600000 | G14: =가정!$B$33*가정!$B$34 -> 1600000 | H14: =가정!$B$33*가정!$B$34 -> 1600000 | I14: =가정!$B$33*가정!$B$34 -> 1600000 | J14: =가정!$B$33*가정!$B$34 -> 1600000 | ... AL14: =가정!$B$33*가정!$B$34 -> 1600000
A15: 매출원가 계 | B15: ₩ | C15: =SUM(C11:C14) -> 1653709.2 | D15: =SUM(D11:D14) -> 1823172.4 | E15: =SUM(E11:E14) -> 2106305.7 | F15: =SUM(F11:F14) -> 2447836.9 | G15: =SUM(G11:G14) -> 2730840 | H15: =SUM(H11:H14) -> 2969946.9 | I15: =SUM(I11:I14) -> 3487722.6 | J15: =SUM(J11:J14) -> 3886624 | ... AL15: =SUM(AL11:AL14) -> 26615719
A16: 매출총이익 | B16: ₩ | C16: =C9-C15 -> -1340371.8 | D16: =D9-D15 -> -521193.44 | E16: =E9-E15 -> 2347461.6 | F16: =F9-F15 -> 3998410 | G16: =G9-G15 -> 6866435.4 | H16: =H9-H15 -> 8022268.6 | I16: =I9-I15 -> 13699233 | J16: =J9-J15 -> 15981257 | ... AL16: =AL9-AL15 -> 1.8950925e+08
A17: 매출총이익률 | B17: % | C17: =IF(C9=0,0,C16/C9) -> -4.277726 | D17: =IF(D9=0,0,D16/D9) -> -0.40030865 | E17: =IF(E9=0,0,E16/E9) -> 0.52707325 | F17: =IF(F9=0,0,F16/F9) -> 0.62026944 | G17: =IF(G9=0,0,G16/G9) -> 0.71545674 | H17: =IF(H9=0,0,H16/H9) -> 0.72981362 | I17: =IF(I9=0,0,I16/I9) -> 0.79707153 | J17: =IF(J9=0,0,J16/J9) -> 0.80437652 | ... AL17: =IF(AL9=0,0,AL16/AL9) -> 0.87685033
A19: 인건비 (부대비 포함) | B19: ₩ | C19: =SUMPRODUCT((가정!$C$49:$C$55<=C3)*가정!$B$49:$B$55)*(1+가정!$B$41) -> 11305000 | D19: =SUMPRODUCT((가정!$C$49:$C$55<=D3)*가정!$B$49:$B$55)*(1+가정!$B$41) -> 11305000 | E19: =SUMPRODUCT((가정!$C$49:$C$55<=E3)*가정!$B$49:$B$55)*(1+가정!$B$41) -> 11305000 | F19: =SUMPRODUCT((가정!$C$49:$C$55<=F3)*가정!$B$49:$B$55)*(1+가정!$B$41) -> 11305000 | G19: =SUMPRODUCT((가정!$C$49:$C$55<=G3)*가정!$B$49:$B$55)*(1+가정!$B$41) -> 11305000 | H19: =SUMPRODUCT((가정!$C$49:$C$55<=H3)*가정!$B$49:$B$55)*(1+가정!$B$41) -> 11305000 | I19: =SUMPRODUCT((가정!$C$49:$C$55<=I3)*가정!$B$49:$B$55)*(1+가정!$B$41) -> 14875000 | J19: =SUMPRODUCT((가정!$C$49:$C$55<=J3)*가정!$B$49:$B$55)*(1+가정!$B$41) -> 14875000 | ... AL19: =SUMPRODUCT((가정!$C$49:$C$55<=AL3)*가정!$B$49:$B$55)*(1+가정!$B$41) -> 26775000
A20: 마케팅비 | B20: ₩ | C20: =가입자!C11 -> 0 | D20: =가입자!D11 -> 1000000 | E20: =가입자!E11 -> 2000000 | F20: =가입자!F11 -> 3000000 | G20: =가입자!G11 -> 3000000 | H20: =가입자!H11 -> 3000000 | I20: =가입자!I11 -> 5000000 | J20: =가입자!J11 -> 5000000 | ... AL20: =가입자!AL11 -> 30000000
A21: 기타 고정비 | B21: ₩ | C21: =가정!$B$57 -> 2500000 | D21: =가정!$B$57 -> 2500000 | E21: =가정!$B$57 -> 2500000 | F21: =가정!$B$57 -> 2500000 | G21: =가정!$B$57 -> 2500000 | H21: =가정!$B$57 -> 2500000 | I21: =가정!$B$57 -> 2500000 | J21: =가정!$B$57 -> 2500000 | ... AL21: =가정!$B$57 -> 2500000
A22: 판관비 계 | B22: ₩ | C22: =SUM(C19:C21) -> 13805000 | D22: =SUM(D19:D21) -> 14805000 | E22: =SUM(E19:E21) -> 15805000 | F22: =SUM(F19:F21) -> 16805000 | G22: =SUM(G19:G21) -> 16805000 | H22: =SUM(H19:H21) -> 16805000 | I22: =SUM(I19:I21) -> 22375000 | J22: =SUM(J19:J21) -> 22375000 | ... AL22: =SUM(AL19:AL21) -> 59275000
A24: 영업이익 | B24: ₩ | C24: =C16-C22 -> -15145372 | D24: =D16-D22 -> -15326193 | E24: =E16-E22 -> -13457538 | F24: =F16-F22 -> -12806590 | G24: =G16-G22 -> -9938564.6 | H24: =H16-H22 -> -8782731.4 | I24: =I16-I22 -> -8675767 | J24: =J16-J22 -> -6393742.6 | ... AL24: =AL16-AL22 -> 1.3023425e+08
A25: 누적 영업이익 | B25: ₩ | C25: =C24 -> -15145372 | D25: =C25+D24 -> -30471565 | E25: =D25+E24 -> -43929104 | F25: =E25+F24 -> -56735694 | G25: =F25+G24 -> -66674258 | H25: =G25+H24 -> -75456990 | I25: =H25+I24 -> -84132757 | J25: =I25+J24 -> -90526499 | K25: =J25+K24 -> -93227418 | ... AL25: =AK25+AL24 -> 1.3369511e+09
A27: 주: 법인세는 흑자 전환 전 0. 흑자 후 창업중소기업 세액감면(본점 소재지별 50~100%, 5년, 연 5억 한도) 적용 검토 — 문서 §7 참조
A28: 주2: 콘텐츠 소진 — 5세 재시청 계수 1.6 반영(플레이테스트 F8)으로 소진 경보 임계 완화. 회고 재생은 신규 소비로 계상하지 않음.

Sheet 현금
A1: 현금흐름 · 런웨이 (VAT 포함 수금/지급 기준)
A3: 월 (M) | C3: 1 | D3: 2 | E3: 3 | F3: 4 | G3: 5 | H3: 6 | I3: 7 | J3: 8 | K3: 9 | L3: 10 | M3: 11 | N3: 12 | O3: 13 | P3: 14 | Q3: 15 | R3: 16 | S3: 17 | T3: 18 | U3: 19 | V3: 20 | W3: 21 | X3: 22 | Y3: 23 | Z3: 24 | AA3: 25 | AB3: 26 | AC3: 27 | AD3: 28 | AE3: 29 | AF3: 30 | AG3: 31 | AH3: 32 | AI3: 33 | AJ3: 34 | AK3: 35 | AL3: 36
A4: 연월 | C4: 2026-07 | D4: 2026-08 | E4: 2026-09 | F4: 2026-10 | G4: 2026-11 | H4: 2026-12 | I4: 2027-01 | J4: 2027-02 | K4: 2027-03 | L4: 2027-04 | M4: 2027-05 | N4: 2027-06 | O4: 2027-07 | P4: 2027-08 | Q4: 2027-09 | R4: 2027-10 | S4: 2027-11 | T4: 2027-12 | U4: 2028-01 | V4: 2028-02 | W4: 2028-03 | X4: 2028-04 | Y4: 2028-05 | Z4: 2028-06 | AA4: 2028-07 | AB4: 2028-08 | AC4: 2028-09 | AD4: 2028-10 | AE4: 2028-11 | AF4: 2028-12 | AG4: 2029-01 | AH4: 2029-02 | AI4: 2029-03 | AJ4: 2029-04 | AK4: 2029-05 | AL4: 2029-06
A6: B2C 수금 (VAT포함) | B6: ₩ | C6: =가입자!C18*가입자!C19+가입자!C20+가입자!C16*가정!$B$14 -> 344671.2 | D6: =가입자!D18*가입자!D19+가입자!D20+가입자!D16*가정!$B$14 -> 1432176.9 | E6: =가입자!E18*가입자!E19+가입자!E20+가입자!E16*가정!$B$14 -> 3249144 | F6: =가입자!F18*가입자!F19+가입자!F20+가입자!F16*가정!$B$14 -> 5440871.6 | G6: =가입자!G18*가입자!G19+가입자!G20+가입자!G16*가정!$B$14 -> 7257002.9 | H6: =가입자!H18*가입자!H19+가입자!H20+가입자!H16*가정!$B$14 -> 8791437 | I6: =가입자!I18*가입자!I19+가입자!I20+가입자!I16*가정!$B$14 -> 13955651 | J6: =가입자!J18*가입자!J19+가입자!J20+가입자!J16*가정!$B$14 -> 16904670 | ... AL6: =가입자!AL18*가입자!AL19+가입자!AL20+가입자!AL16*가정!$B$14 -> 1.8493747e+08
A7: B2G 수금 (VAT포함) | B7: ₩ | C7: =손익!C8*(1+가정!$B$40) -> 0 | D7: =손익!D8*(1+가정!$B$40) -> 0 | E7: =손익!E8*(1+가정!$B$40) -> 1650000 | F7: =손익!F8*(1+가정!$B$40) -> 1650000 | G7: =손익!G8*(1+가정!$B$40) -> 3300000 | H7: =손익!H8*(1+가정!$B$40) -> 3300000 | I7: =손익!I8*(1+가정!$B$40) -> 4950000 | J7: =손익!J8*(1+가정!$B$40) -> 4950000 | ... AL7: =손익!AL8*(1+가정!$B$40) -> 52800000
A8: 정부지원금 [입력] | B8: ₩ | C8: 0 | D8: 30000000 | E8: 0 | F8: 0 | G8: 0 | H8: 0 | I8: 0 | J8: 0 | K8: 0 | L8: 0 | M8: 0 | N8: 0 | O8: 0 | P8: 0 | Q8: 0 | R8: 0 | S8: 0 | T8: 0 | U8: 0 | V8: 0 | W8: 0 | X8: 0 | Y8: 0 | Z8: 0 | AA8: 0 | AB8: 0 | AC8: 0 | AD8: 0 | AE8: 0 | AF8: 0 | AG8: 0 | AH8: 0 | AI8: 0 | AJ8: 0 | AK8: 0 | AL8: 0
A9: Seed 납입 | B9: ₩ | C9: =가정!$B$44 -> 300000000 | D9: 0 | E9: 0 | F9: 0 | G9: 0 | H9: 0 | I9: 0 | J9: 0 | K9: 0 | L9: 0 | M9: 0 | N9: 0 | O9: 0 | P9: 0 | Q9: 0 | R9: 0 | S9: 0 | T9: 0 | U9: 0 | V9: 0 | W9: 0 | X9: 0 | Y9: 0 | Z9: 0 | AA9: 0 | AB9: 0 | AC9: 0 | AD9: 0 | AE9: 0 | AF9: 0 | AG9: 0 | AH9: 0 | AI9: 0 | AJ9: 0 | AK9: 0 | AL9: 0
A10: 유입 계 | B10: ₩ | C10: =SUM(C6:C9) -> 3.0034467e+08 | D10: =SUM(D6:D9) -> 31432177 | E10: =SUM(E6:E9) -> 4899144 | F10: =SUM(F6:F9) -> 7090871.6 | G10: =SUM(G6:G9) -> 10557003 | H10: =SUM(H6:H9) -> 12091437 | I10: =SUM(I6:I9) -> 18905651 | J10: =SUM(J6:J9) -> 21854670 | ... AL10: =SUM(AL6:AL9) -> 2.3773747e+08
A12: 매출원가 지급 | B12: ₩ | C12: =손익!C15 -> 1653709.2 | D12: =손익!D15 -> 1823172.4 | E12: =손익!E15 -> 2106305.7 | F12: =손익!F15 -> 2447836.9 | G12: =손익!G15 -> 2730840 | H12: =손익!H15 -> 2969946.9 | I12: =손익!I15 -> 3487722.6 | J12: =손익!J15 -> 3886624 | ... AL12: =손익!AL15 -> 26615719
A13: 판관비 지급 | B13: ₩ | C13: =손익!C22 -> 13805000 | D13: =손익!D22 -> 14805000 | E13: =손익!E22 -> 15805000 | F13: =손익!F22 -> 16805000 | G13: =손익!G22 -> 16805000 | H13: =손익!H22 -> 16805000 | I13: =손익!I22 -> 22375000 | J13: =손익!J22 -> 22375000 | ... AL13: =손익!AL22 -> 59275000
A14: 부가세 순납부 (분기, 간이추정) | B14: ₩ | C14: 0 | D14: 0 | E14: 0 | F14: =MAX(0,(SUM(손익!C9:E9)-SUM(손익!C14:E14)-SUM(손익!C20:E20)-SUM(손익!C21:E21))*가정!$B$40) -> 0 | G14: 0 | H14: 0 | I14: =MAX(0,(SUM(손익!F9:H9)-SUM(손익!F14:H14)-SUM(손익!F20:H20)-SUM(손익!F21:H21))*가정!$B$40) -> 573573.77 | J14: 0 | K14: 0 | L14: =MAX(0,(SUM(손익!I9:K9)-SUM(손익!I14:K14)-SUM(손익!I20:K20)-SUM(손익!I21:K21))*가정!$B$40) -> 3369885.2 | M14: 0 | N14: 0 | O14: =MAX(0,(SUM(손익!L9:N9)-SUM(손익!L14:N14)-SUM(손익!L20:N20)-SUM(손익!L21:N21))*가정!$B$40) -> 6273112 | P14: 0 | Q14: 0 | R14: =MAX(0,(SUM(손익!O9:Q9)-SUM(손익!O14:Q14)-SUM(손익!O20:Q20)-SUM(손익!O21:Q21))*가정!$B$40) -> 10245323 | S14: 0 | T14: 0 | U14: =MAX(0,(SUM(손익!R9:T9)-SUM(손익!R14:T14)-SUM(손익!R20:T20)-SUM(손익!R21:T21))*가정!$B$40) -> 14813118 | V14: 0 | W14: 0 | X14: =MAX(0,(SUM(손익!U9:W9)-SUM(손익!U14:W14)-SUM(손익!U20:W20)-SUM(손익!U21:W21))*가정!$B$40) -> 19498741 | Y14: 0 | Z14: 0 | AA14: =MAX(0,(SUM(손익!X9:Z9)-SUM(손익!X14:Z14)-SUM(손익!X20:Z20)-SUM(손익!X21:Z21))*가정!$B$40) -> 25923069 | AB14: 0 | AC14: 0 | AD14: =MAX(0,(SUM(손익!AA9:AC9)-SUM(손익!AA14:AC14)-SUM(손익!AA20:AC20)-SUM(손익!AA21:AC21))*가정!$B$40) -> 32486095 | AE14: 0 | AF14: 0 | AG14: =MAX(0,(SUM(손익!AD9:AF9)-SUM(손익!AD14:AF14)-SUM(손익!AD20:AF20)-SUM(손익!AD21:AF21))*가정!$B$40) -> 40955798 | AH14: 0 | AI14: 0 | AJ14: =MAX(0,(SUM(손익!AG9:AI9)-SUM(손익!AG14:AI14)-SUM(손익!AG20:AI20)-SUM(손익!AG21:AI21))*가정!$B$40) -> 47167663 | AK14: 0 | AL14: 0
A15: 유출 계 | B15: ₩ | C15: =SUM(C12:C14) -> 15458709 | D15: =SUM(D12:D14) -> 16628172 | E15: =SUM(E12:E14) -> 17911306 | F15: =SUM(F12:F14) -> 19252837 | G15: =SUM(G12:G14) -> 19535840 | H15: =SUM(H12:H14) -> 19774947 | I15: =SUM(I12:I14) -> 26436296 | J15: =SUM(J12:J14) -> 26261624 | ... AL15: =SUM(AL12:AL14) -> 85890719
A17: 순현금흐름 | B17: ₩ | C17: =C10-C15 -> 2.8488596e+08 | D17: =D10-D15 -> 14804004 | E17: =E10-E15 -> -13012162 | F17: =F10-F15 -> -12161965 | G17: =G10-G15 -> -8978837.1 | H17: =H10-H15 -> -7683509.9 | I17: =I10-I15 -> -7530645.2 | J17: =J10-J15 -> -4406954.4 | ... AL17: =AL10-AL15 -> 1.5184675e+08
A18: 기초 현금 | B18: ₩ | C18: 0 | D18: =C19 -> 2.8488596e+08 | E18: =D19 -> 2.9968997e+08 | F18: =E19 -> 2.866778e+08 | G18: =F19 -> 2.7451584e+08 | H18: =G19 -> 2.65537e+08 | I18: =H19 -> 2.5785349e+08 | J18: =I19 -> 2.5032285e+08 | K18: =J19 -> 2.4591589e+08 | ... AL18: =AK19 -> 1.6418582e+09
A19: 기말 현금 | B19: ₩ | C19: =C17 -> 2.8488596e+08 | D19: =D18+D17 -> 2.9968997e+08 | E19: =E18+E17 -> 2.866778e+08 | F19: =F18+F17 -> 2.7451584e+08 | G19: =G18+G17 -> 2.65537e+08 | H19: =H18+H17 -> 2.5785349e+08 | I19: =I18+I17 -> 2.5032285e+08 | J19: =J18+J17 -> 2.4591589e+08 | K19: =K18+K17 -> 2.4560938e+08 | ... AL19: =AL18+AL17 -> 1.7937049e+09
A20: 런웨이 (개월, 최근3M 소진 기준) | B20: 개월 | C20: =IF(C19<=0,"소진",IF(AVERAGE(C17:C17)>=0,"흑자권",ROUND(C19/ABS(AVERAGE(C17:C17)),1))) -> 흑자권 | D20: =IF(D19<=0,"소진",IF(AVERAGE(C17:D17)>=0,"흑자권",ROUND(D19/ABS(AVERAGE(C17:D17)),1))) -> 흑자권 | E20: =IF(E19<=0,"소진",IF(AVERAGE(C17:E17)>=0,"흑자권",ROUND(E19/ABS(AVERAGE(C17:E17)),1))) -> 흑자권 | F20: =IF(F19<=0,"소진",IF(AVERAGE(D17:F17)>=0,"흑자권",ROUND(F19/ABS(AVERAGE(D17:F17)),1))) -> 79.4 | G20: =IF(G19<=0,"소진",IF(AVERAGE(E17:G17)>=0,"흑자권",ROUND(G19/ABS(AVERAGE(E17:G17)),1))) -> 23.3 | H20: =IF(H19<=0,"소진",IF(AVERAGE(F17:H17)>=0,"흑자권",ROUND(H19/ABS(AVERAGE(F17:H17)),1))) -> 26.8 | I20: =IF(I19<=0,"소진",IF(AVERAGE(G17:I17)>=0,"흑자권",ROUND(I19/ABS(AVERAGE(G17:I17)),1))) -> 31 | J20: =IF(J19<=0,"소진",IF(AVERAGE(H17:J17)>=0,"흑자권",ROUND(J19/ABS(AVERAGE(H17:J17)),1))) -> 37.6 | K20: =IF(K19<=0,"소진",IF(AVERAGE(I17:K17)>=0,"흑자권",ROUND(K19/ABS(AVERAGE(I17:K17)),1))) -> 60.2 | L20: =IF(L19<=0,"소진",IF(AVERAGE(J17:L17)>=0,"흑자권",ROUND(L19/ABS(AVERAGE(J17:L17)),1))) -> 75.8 | ... AL20: =IF(AL19<=0,"소진",IF(AVERAGE(AJ17:AL17)>=0,"흑자권",ROUND(AL19/ABS(AVERAGE(AJ17:AL17)),1))) -> 흑자권
A21: (메모) 선수수익 잔액 | B21: ₩ | C21: =가입자!C16*가정!$B$14/(1+가정!$B$40)-가입자!C17*가정!$B$14/12/(1+가정!$B$40) -> 0 | D21: =C21+가입자!D16*가정!$B$14/(1+가정!$B$40)-가입자!D17*가정!$B$14/12/(1+가정!$B$40) -> 0 | E21: =D21+가입자!E16*가정!$B$14/(1+가정!$B$40)-가입자!E17*가정!$B$14/12/(1+가정!$B$40) -> 0 | F21: =E21+가입자!F16*가정!$B$14/(1+가정!$B$40)-가입자!F17*가정!$B$14/12/(1+가정!$B$40) -> 0 | G21: =F21+가입자!G16*가정!$B$14/(1+가정!$B$40)-가입자!G17*가정!$B$14/12/(1+가정!$B$40) -> 0 | H21: =G21+가입자!H16*가정!$B$14/(1+가정!$B$40)-가입자!H17*가정!$B$14/12/(1+가정!$B$40) -> 0 | I21: =H21+가입자!I16*가정!$B$14/(1+가정!$B$40)-가입자!I17*가정!$B$14/12/(1+가정!$B$40) -> 0 | J21: =I21+가입자!J16*가정!$B$14/(1+가정!$B$40)-가입자!J17*가정!$B$14/12/(1+가정!$B$40) -> 0 | K21: =J21+가입자!K16*가정!$B$14/(1+가정!$B$40)-가입자!K17*가정!$B$14/12/(1+가정!$B$40) -> 0 | ... AL21: =AK21+가입자!AL16*가정!$B$14/(1+가정!$B$40)-가입자!AL17*가정!$B$14/12/(1+가정!$B$40) -> 0
A23: 주: B2G는 발생=수금 가정(실제 계약 시 선수금 협상으로 개선 여지). 부가세는 인건비 매입세액 없음 반영한 간이 추정.

Sheet 유닛
A1: 유닛 이코노믹스 · 민감도 · BEP · 마일스톤
A3: A. 유닛 이코노믹스 정본 (정가 기준)
A4: 정가 월 구독료 (VAT포함) | B4: =가정!$B$8 -> 25000
A5: 순 ARPU (VAT제외) | B5: =B4/(1+가정!$B$40) -> 22727.273
A6: 가구당 월 변동원가 | B6: =B4*가정!$B$28+가정!$B$29+가정!$B$67 -> 3250
A7: 가구당 월 공헌이익 | B7: =B5-B6 -> 19477.273
A8: 공헌마진율 | B8: =B7/B5 -> 0.857
A9: 월 이탈률 (시나리오) | B9: =가정!$B$22 -> 0.25
A10: 평균 구독기간 (개월) | B10: =1/B9 -> 4
A11: 매출 LTV (순매출 기준) | B11: =B5*B10 -> 90909.091
A12: 공헌이익 LTV ★의사결정 기준 | B12: =B7*B10 -> 77909.091
A13: Paid CAC | B13: =가정!$B$25 -> 30000
A14: LTV/CAC (공헌이익 기준) | B14: =B12/B13 -> 2.5969697
A15: CAC 회수기간 (개월) | B15: =B13/B7 -> 1.5402567
A16: LTV/CAC 3.0x 허용 최대 CAC | B16: =B12/3 -> 25969.697
A19: B. 공헌이익 LTV 민감도 (행=월이탈률, 열=월가격 VAT포함)
C20: 19000 | D20: 25000 | E20: 29000
B21: 0.15 | C21: =(C$20/(1+가정!$B$40)-(C$20*가정!$B$28+가정!$B$29+가정!$B$30))/$B21 -> 102178.18 | D21: =(D$20/(1+가정!$B$40)-(D$20*가정!$B$28+가정!$B$29+가정!$B$30))/$B21 -> 137181.82 | E21: =(E$20/(1+가정!$B$40)-(E$20*가정!$B$28+가정!$B$29+가정!$B$30))/$B21 -> 160517.58
B22: 0.2 | C22: =(C$20/(1+가정!$B$40)-(C$20*가정!$B$28+가정!$B$29+가정!$B$30))/$B22 -> 76633.636 | D22: =(D$20/(1+가정!$B$40)-(D$20*가정!$B$28+가정!$B$29+가정!$B$30))/$B22 -> 102886.36 | E22: =(E$20/(1+가정!$B$40)-(E$20*가정!$B$28+가정!$B$29+가정!$B$30))/$B22 -> 120388.18
B23: 0.25 | C23: =(C$20/(1+가정!$B$40)-(C$20*가정!$B$28+가정!$B$29+가정!$B$30))/$B23 -> 61306.909 | D23: =(D$20/(1+가정!$B$40)-(D$20*가정!$B$28+가정!$B$29+가정!$B$30))/$B23 -> 82309.091 | E23: =(E$20/(1+가정!$B$40)-(E$20*가정!$B$28+가정!$B$29+가정!$B$30))/$B23 -> 96310.545
B24: 0.3 | C24: =(C$20/(1+가정!$B$40)-(C$20*가정!$B$28+가정!$B$29+가정!$B$30))/$B24 -> 51089.091 | D24: =(D$20/(1+가정!$B$40)-(D$20*가정!$B$28+가정!$B$29+가정!$B$30))/$B24 -> 68590.909 | E24: =(E$20/(1+가정!$B$40)-(E$20*가정!$B$28+가정!$B$29+가정!$B$30))/$B24 -> 80258.788
B25: 0.35 | C25: =(C$20/(1+가정!$B$40)-(C$20*가정!$B$28+가정!$B$29+가정!$B$30))/$B25 -> 43790.649 | D25: =(D$20/(1+가정!$B$40)-(D$20*가정!$B$28+가정!$B$29+가정!$B$30))/$B25 -> 58792.208 | E25: =(E$20/(1+가정!$B$40)-(E$20*가정!$B$28+가정!$B$29+가정!$B$30))/$B25 -> 68793.247
A28: C. 손익분기점 (BEP)
A29: 월 고정비 — 팀 급여 포함 (M12 기준) | B29: =손익!N19+손익!N21+손익!N14 -> 21355000
A30: BEP 유료 가구 (팀 포함) | B30: =B29/B7 -> 1096.4061
A31: 월 고정비 — 운영 최소 (인건비 제외) | B31: =손익!N21+손익!N14 -> 4100000
A32: BEP 유료 가구 (운영 최소) | B32: =B31/B7 -> 210.50175
A33: 검증: 백서 v1.1 §8.3 = 운영최소 200명 / 팀포함 800명 (인건비 1,200만 가정) — 본 모델과 정합 확인용
A35: D. 마일스톤 체크 (IR 로드맵 대비)
A36: 마일스톤 | B36: 목표 | C36: 모델값 | D36: 판정 | E36: 갭
A37: M+2 유료 가구 (스프린트) | B37: 20 | C37: =가입자!D15 -> 72.699333 | D37: =IF(C37>=B37,"달성","미달") -> 달성 | E37: =C37-B37 -> 52.699333
A38: M+9 유료 가구 (Pre-A 트리거) | B38: 1000 | C38: =가입자!K15 -> 832.84457 | D38: =IF(C38>=B38,"달성","미달") -> 미달 | E38: =C38-B38 -> -167.15543
A39: M+18 유료 가구 (Series A) | B39: 10000 | C39: =가입자!T15 -> 2562.64 | D39: =IF(C39>=B39,"달성","미달") -> 미달 | E39: =C39-B39 -> -7437.36
A41: 월 MRR (M+9, 순매출) | B41: =가입자!K22 -> 17944015
A42: ARR 런레이트 (M+12, B2C+B2G) | B42: =손익!N9*12 -> 4.4389462e+08
A45: E. 얼리버드(₩19,000) 유닛 & 코호트별 paid CAC 게이트 [v1.1]
A46: 얼리버드 월가 (VAT포함) | B46: =가정!$B$7 -> 19000
A47: 순 ARPU | B47: =B46/(1+가정!$B$40) -> 17272.727
A48: 월 변동원가 | B48: =B46*가정!$B$28+가정!$B$29+가정!$B$30 -> 1946
A49: 월 공헌이익 | B49: =B47-B48 -> 15326.727
...
